<?xml version="1.0" encoding="utf-8"?>
<!-- This URDF was automatically created by SolidWorks to URDF Exporter! Originally created by Stephen Brawner (brawner@gmail.com) 
     Commit Version: 1.6.0-4-g7f85cfe  Build Version: 1.6.7995.38578
     For more information, please see http://wiki.ros.org/sw_urdf_exporter -->
<robot
  name="Assembly.SLDASM">
  <link
    name="base_link">
    <inertial>
      <origin
        xyz="4.1638E-18 -0.0099501 0.03"
        rpy="0 0 0" />
      <mass
        value="2.2532" />
      <inertia
        ixx="0.0027726"
        ixy="5.064E-20"
        ixz="7.5802E-20"
        iyy="0.0053916"
        iyz="1.4088E-20"
        izz="0.0027727" />
    </inertial>
    <visual>
      <origin
        xyz="0 0 0"
        rpy="0 0 0" />
      <geometry>
        <mesh
          filename="package://Assembly.SLDASM/meshes/base_link.STL" />
      </geometry>
      <material
        name="">
        <color
          rgba="0.52941 0.54902 0.54902 1" />
      </material>
    </visual>
    <collision>
      <origin
        xyz="0 0 0"
        rpy="0 0 0" />
      <geometry>
        <mesh
          filename="package://Assembly.SLDASM/meshes/base_link.STL" />
      </geometry>
    </collision>
  </link>
  <link
    name="link1">
    <inertial>
      <origin
        xyz="0.0175 -0.0075 -2.0201E-15"
        rpy="0 0 0" />
      <mass
        value="0.0057358" />
      <inertia
        ixx="2.1463E-07"
        ixy="-1.4818E-22"
        ixz="-1.7205E-22"
        iyy="7.0203E-07"
        iyz="3.503E-23"
        izz="7.1625E-07" />
    </inertial>
    <visual>
      <origin
        xyz="0 0 0"
        rpy="0 0 0" />
      <geometry>
        <mesh
          filename="package://Assembly.SLDASM/meshes/link1.STL" />
      </geometry>
      <material
        name="">
        <color
          rgba="0.79216 0.81961 0.93333 1" />
      </material>
    </visual>
    <collision>
      <origin
        xyz="0 0 0"
        rpy="0 0 0" />
      <geometry>
        <mesh
          filename="package://Assembly.SLDASM/meshes/link1.STL" />
      </geometry>
    </collision>
  </link>
  <joint
    name="joint0"
    type="revolute">
    <origin
      xyz="0 -0.0225 0.008"
      rpy="3.1416 -1.0462 3.1416" />
    <parent
      link="base_link" />
    <child
      link="link1" />
    <axis
      xyz="0 1 0" />
    <limit
      lower="-1.57"
      upper="1.57"
      effort="10"
      velocity="100" />
  </joint>
  <link
    name="link2">
    <inertial>
      <origin
        xyz="0.0175 0.0075 -2.2309E-15"
        rpy="0 0 0" />
      <mass
        value="0.0057358" />
      <inertia
        ixx="2.1463E-07"
        ixy="2.4975E-22"
        ixz="-9.2644E-23"
        iyy="7.0203E-07"
        iyz="5.2061E-24"
        izz="7.1625E-07" />
    </inertial>
    <visual>
      <origin
        xyz="0 0 0"
        rpy="0 0 0" />
      <geometry>
        <mesh
          filename="package://Assembly.SLDASM/meshes/link2.STL" />
      </geometry>
      <material
        name="">
        <color
          rgba="0.79216 0.81961 0.93333 1" />
      </material>
    </visual>
    <collision>
      <origin
        xyz="0 0 0"
        rpy="0 0 0" />
      <geometry>
        <mesh
          filename="package://Assembly.SLDASM/meshes/link2.STL" />
      </geometry>
    </collision>
  </link>
  <joint
    name="joint1"
    type="revolute">
    <origin
      xyz="0.035 0 0"
      rpy="-3.1416 0.741 0" />
    <parent
      link="link1" />
    <child
      link="link2" />
    <axis
      xyz="0 1 0" />
    <limit
      lower="-1.57"
      upper="1.57"
      effort="10"
      velocity="100" />
  </joint>
  <link
    name="fingertip">
    <inertial>
      <origin
        xyz="0.021444 -0.0075 0.00036377"
        rpy="0 0 0" />
      <mass
        value="0.0075224" />
      <inertia
        ixx="2.7488E-07"
        ixy="-1.2304E-16"
        ixz="-4.6053E-08"
        iyy="1.1261E-06"
        iyz="-2.4426E-17"
        izz="1.1611E-06" />
    </inertial>
    <visual>
      <origin
        xyz="0 0 0"
        rpy="0 0 0" />
      <geometry>
        <mesh
          filename="package://Assembly.SLDASM/meshes/fingertip.STL" />
      </geometry>
      <material
        name="">
        <color
          rgba="0.79216 0.81961 0.93333 1" />
      </material>
    </visual>
    <collision>
      <origin
        xyz="0 0 0"
        rpy="0 0 0" />
      <geometry>
        <mesh
          filename="package://Assembly.SLDASM/meshes/fingertip.STL" />
      </geometry>
    </collision>
  </link>
  <joint
    name="joint2"
    type="revolute">
    <origin
      xyz="0.035 0 0"
      rpy="3.1416 -0.15223 0" />
    <parent
      link="link2" />
    <child
      link="fingertip" />
    <axis
      xyz="0 1 0" />
    <limit
      lower="-1.57"
      upper="1.57"
      effort="10"
      velocity="100" />
  </joint>
</robot>