<?xml version="1.0" encoding="utf-8"?>
<!-- This URDF was automatically created by SolidWorks to URDF Exporter! Originally created by Stephen Brawner (brawner@gmail.com) 
     Commit Version: 1.6.0-4-g7f85cfe  Build Version: 1.6.7995.38578
     For more information, please see http://wiki.ros.org/sw_urdf_exporter -->
<robot
  name="finger">
  <link
    name="base_link">
    <inertial>
      <origin
        xyz="4.16197290784397E-18 -0.00993974748653739 0.0300014235592228"
        rpy="0 0 0" />
      <mass
        value="2.25446767524272" />
      <inertia
        ixx="0.00277268478631531"
        ixy="5.06396775501893E-20"
        ixz="7.58027467186751E-20"
        iyy="0.00539162126185719"
        iyz="1.40890952655998E-20"
        izz="0.00277273425968255" />
    </inertial>
    <visual>
      <origin
        xyz="0 0 0"
        rpy="0 0 0" />
      <geometry>
        <mesh
          filename="package://finger/meshes/base_link.STL" />
      </geometry>
      <material
        name="">
        <color
          rgba="0.529411764705882 0.549019607843137 0.549019607843137 1" />
      </material>
    </visual>
    <collision>
      <origin
        xyz="0 0 0"
        rpy="0 0 0" />
      <geometry>
        <mesh
          filename="package://finger/meshes/base_link.STL" />
      </geometry>
    </collision>
  </link>
  <link
    name="link_1">
    <inertial>
      <origin
        xyz="0.0207393229920771 -0.0079559655758786 2.6628005356244E-16"
        rpy="0 0 0" />
      <mass
        value="0.00703861962695465" />
      <inertia
        ixx="2.62020669315562E-07"
        ixy="-1.37212946526911E-22"
        ixz="-9.26442286059392E-23"
        iyy="7.16921529606444E-07"
        iyz="-1.1772685729731E-23"
        izz="7.63643073331604E-07" />
    </inertial>
    <visual>
      <origin
        xyz="0 0 0"
        rpy="0 0 0" />
      <geometry>
        <mesh
          filename="package://finger/meshes/link_1.STL" />
      </geometry>
      <material
        name="">
        <color
          rgba="0.792156862745098 0.819607843137255 0.933333333333333 1" />
      </material>
    </visual>
    <collision>
      <origin
        xyz="0 0 0"
        rpy="0 0 0" />
      <geometry>
        <mesh
          filename="package://finger/meshes/link_1.STL" />
      </geometry>
    </collision>
  </link>
  <joint
    name="joint_1"
    type="revolute">
    <origin
      xyz="0 -0.0225 0.008"
      rpy="3.1416 -1.0462 3.1416" />
    <parent
      link="base_link" />
    <child
      link="link_1" />
    <axis
      xyz="0 0 1" />
    <limit
      lower="-1.57"
      upper="1.57"
      effort="10"
      velocity="100" />
  </joint>
  <link
    name="link_2">
    <inertial>
      <origin
        xyz="0.0207393229920767 0.00795596557587861 -1.68962066560141E-15"
        rpy="0 0 0" />
      <mass
        value="0.00703861962695465" />
      <inertia
        ixx="2.62020669315562E-07"
        ixy="2.5086774228277E-22"
        ixz="-3.97046694025453E-23"
        iyy="7.16921529606444E-07"
        iyz="1.06410424434208E-23"
        izz="7.63643073331604E-07" />
    </inertial>
    <visual>
      <origin
        xyz="0 0 0"
        rpy="0 0 0" />
      <geometry>
        <mesh
          filename="package://finger/meshes/link_2.STL" />
      </geometry>
      <material
        name="">
        <color
          rgba="0.792156862745098 0.819607843137255 0.933333333333333 1" />
      </material>
    </visual>
    <collision>
      <origin
        xyz="0 0 0"
        rpy="0 0 0" />
      <geometry>
        <mesh
          filename="package://finger/meshes/link_2.STL" />
      </geometry>
    </collision>
  </link>
  <joint
    name="joint_2"
    type="revolute">
    <origin
      xyz="0.035 0 0"
      rpy="-3.1416 0.741 0" />
    <parent
      link="link_1" />
    <child
      link="link_2" />
    <axis
      xyz="0 0 1" />
    <limit
      lower="-1.57"
      upper="1.57"
      effort="10"
      velocity="100" />
  </joint>
  <link
    name="end_link">
    <inertial>
      <origin
        xyz="0.0214441157580334 -0.00749999999899945 0.000363766379080151"
        rpy="0 0 0" />
      <mass
        value="0.00752238112648173" />
      <inertia
        ixx="2.74880881878481E-07"
        ixy="-1.23037035124277E-16"
        ixz="-4.60531164771404E-08"
        iyy="1.12605308893331E-06"
        iyz="-2.44263405116846E-17"
        izz="1.16112796100964E-06" />
    </inertial>
    <visual>
      <origin
        xyz="0 0 0"
        rpy="0 0 0" />
      <geometry>
        <mesh
          filename="package://finger/meshes/end_link.STL" />
      </geometry>
      <material
        name="">
        <color
          rgba="0.792156862745098 0.819607843137255 0.933333333333333 1" />
      </material>
    </visual>
    <collision>
      <origin
        xyz="0 0 0"
        rpy="0 0 0" />
      <geometry>
        <mesh
          filename="package://finger/meshes/end_link.STL" />
      </geometry>
    </collision>
  </link>
  <joint
    name="end_joint"
    type="revolute">
    <origin
      xyz="0.035 0 0"
      rpy="3.1416 -0.15223 0" />
    <parent
      link="link_2" />
    <child
      link="end_link" />
    <axis
      xyz="0 0 1" />
    <limit
      lower="-1.57"
      upper="1.57"
      effort="10"
      velocity="100" />
  </joint>
</robot>